Workbook

Sheet Dashboard
B2: CONSTRUCTION PROJECT FINANCE MODEL — DASHBOARD
B4: Project Name: | C4: Akademie — U26/73-75 Centennial Circuit Byron Bay
B5: Client: | C5: Akademie Pty Ltd
B6: Builder / PM:
B7: Report Date: | C7: =TODAY() -> 46086
B9: PROJECT FINANCIAL SNAPSHOT (excl. GST)
B10: Original Budget ($) | D10: Approved Variations ($) | F10: Revised Budget ($) | H10: Actual Cost to Date ($) | J10: FFC ($)
B11: ='BOQ Summary'!D54 -> 0 | D11: ='BOQ Summary'!F54 -> 0 | F11: ='BOQ Summary'!G54 -> 0 | H11: ='BOQ Summary'!I54 -> 0 | J11: ='BOQ Summary'!J54 -> 0
B12: Margin ($) | D12: Total Excl. GST ($) | F12: Variance ($) | H12: % Budget Expended | J12: Budget Balance ($)
B13: ='BOQ Summary'!G54*'BOQ Summary'!$D$6 -> 0 | D13: ='BOQ Summary'!G54*(1+'BOQ Summary'!$D$6) -> 0 | F13: ='BOQ Summary'!K54 -> 0 | H13: =IFERROR('BOQ Summary'!I54/'BOQ Summary'!G54,0) -> 0 | J13: ='BOQ Summary'!L54 -> 0
B15: COST CODE STATUS — LIVE
B16: CC | C16: Description | D16: Original Budget ($) | E16: Approved Variations ($) | F16: Revised Budget ($) | G16: Committed ($) | H16: Actual CTD ($) | I16: FFC ($) | J16: Variance ($) | K16: % Done | L16: RAG
B17: ='BOQ Summary'!B10 -> 001 | C17: ='BOQ Summary'!C10 -> PRELIMINARY COSTS, CONSULTANT FEES, SITE ESTABLISHMENT | D17: ='BOQ Summary'!D10 -> 0 | E17: ='BOQ Summary'!F10 -> 0 | F17: ='BOQ Summary'!G10 -> 0 | G17: ='BOQ Summary'!H10 -> 0 | H17: ='BOQ Summary'!I10 -> 0 | I17: ='BOQ Summary'!J10 -> 0 | J17: ='BOQ Summary'!K10 -> 0 | K17: =IFERROR(H17/F17,0) -> 0 | L17: =IF(F17=0,"—",IF(I17<=F17,"✔ OK",IF(I17<=F17*1.1,"▲ RISK","✖ OVER"))) -> —
B18: ='BOQ Summary'!B11 -> 002 | C18: ='BOQ Summary'!C11 -> SITE HIRE ITEMS | D18: ='BOQ Summary'!D11 -> 0 | E18: ='BOQ Summary'!F11 -> 0 | F18: ='BOQ Summary'!G11 -> 0 | G18: ='BOQ Summary'!H11 -> 0 | H18: ='BOQ Summary'!I11 -> 0 | I18: ='BOQ Summary'!J11 -> 0 | J18: ='BOQ Summary'!K11 -> 0 | K18: =IFERROR(H18/F18,0) -> 0 | L18: =IF(F18=0,"—",IF(I18<=F18,"✔ OK",IF(I18<=F18*1.1,"▲ RISK","✖ OVER"))) -> —
B19: ='BOQ Summary'!B12 -> 003 | C19: ='BOQ Summary'!C12 -> SURVEYING - SET-OUT, TBM, PINS | D19: ='BOQ Summary'!D12 -> 0 | E19: ='BOQ Summary'!F12 -> 0 | F19: ='BOQ Summary'!G12 -> 0 | G19: ='BOQ Summary'!H12 -> 0 | H19: ='BOQ Summary'!I12 -> 0 | I19: ='BOQ Summary'!J12 -> 0 | J19: ='BOQ Summary'!K12 -> 0 | K19: =IFERROR(H19/F19,0) -> 0 | L19: =IF(F19=0,"—",IF(I19<=F19,"✔ OK",IF(I19<=F19*1.1,"▲ RISK","✖ OVER"))) -> —
B20: ='BOQ Summary'!B13 -> 004 | C20: ='BOQ Summary'!C13 -> STRUCTURAL STEEL - SUPPLY AND INSTALLATION | D20: ='BOQ Summary'!D13 -> 0 | E20: ='BOQ Summary'!F13 -> 0 | F20: ='BOQ Summary'!G13 -> 0 | G20: ='BOQ Summary'!H13 -> 0 | H20: ='BOQ Summary'!I13 -> 0 | I20: ='BOQ Summary'!J13 -> 0 | J20: ='BOQ Summary'!K13 -> 0 | K20: =IFERROR(H20/F20,0) -> 0 | L20: =IF(F20=0,"—",IF(I20<=F20,"✔ OK",IF(I20<=F20*1.1,"▲ RISK","✖ OVER"))) -> —
B21: ='BOQ Summary'!B14 -> 005 | C21: ='BOQ Summary'!C14 -> STRUCTURAL CONCRETE - FOUNDATIONS, PIERS, SLAB | D21: ='BOQ Summary'!D14 -> 0 | E21: ='BOQ Summary'!F14 -> 0 | F21: ='BOQ Summary'!G14 -> 0 | G21: ='BOQ Summary'!H14 -> 0 | H21: ='BOQ Summary'!I14 -> 0 | I21: ='BOQ Summary'!J14 -> 0 | J21: ='BOQ Summary'!K14 -> 0 | K21: =IFERROR(H21/F21,0) -> 0 | L21: =IF(F21=0,"—",IF(I21<=F21,"✔ OK",IF(I21<=F21*1.1,"▲ RISK","✖ OVER"))) -> —
B22: ='BOQ Summary'!B15 -> 006 | C22: ='BOQ Summary'!C15 -> DRAINAGE PLUMBING - SEPTIC, STORMWATER, AG-DRAINAGE | D22: ='BOQ Summary'!D15 -> 0 | E22: ='BOQ Summary'!F15 -> 0 | F22: ='BOQ Summary'!G15 -> 0 | G22: ='BOQ Summary'!H15 -> 0 | H22: ='BOQ Summary'!I15 -> 0 | I22: ='BOQ Summary'!J15 -> 0 | J22: ='BOQ Summary'!K15 -> 0 | K22: =IFERROR(H22/F22,0) -> 0 | L22: =IF(F22=0,"—",IF(I22<=F22,"✔ OK",IF(I22<=F22*1.1,"▲ RISK","✖ OVER"))) -> —
B23: ='BOQ Summary'!B16 -> 007 | C23: ='BOQ Summary'!C16 -> MEZZANINE & GALLERY / STORAGE FLOOR FRAMING - TIMBER & HARDWARE | D23: ='BOQ Summary'!D16 -> 0 | E23: ='BOQ Summary'!F16 -> 0 | F23: ='BOQ Summary'!G16 -> 0 | G23: ='BOQ Summary'!H16 -> 0 | H23: ='BOQ Summary'!I16 -> 0 | I23: ='BOQ Summary'!J16 -> 0 | J23: ='BOQ Summary'!K16 -> 0 | K23: =IFERROR(H23/F23,0) -> 0 | L23: =IF(F23=0,"—",IF(I23<=F23,"✔ OK",IF(I23<=F23*1.1,"▲ RISK","✖ OVER"))) -> —
B24: ='BOQ Summary'!B17 -> 008 | C24: ='BOQ Summary'!C17 -> CARPENTRY LABOUR - MEZZANINE FLOOR GRADING & LAYING | D24: ='BOQ Summary'!D17 -> 0 | E24: ='BOQ Summary'!F17 -> 0 | F24: ='BOQ Summary'!G17 -> 0 | G24: ='BOQ Summary'!H17 -> 0 | H24: ='BOQ Summary'!I17 -> 0 | I24: ='BOQ Summary'!J17 -> 0 | J24: ='BOQ Summary'!K17 -> 0 | K24: =IFERROR(H24/F24,0) -> 0 | L24: =IF(F24=0,"—",IF(I24<=F24,"✔ OK",IF(I24<=F24*1.1,"▲ RISK","✖ OVER"))) -> —
B25: ='BOQ Summary'!B18 -> 009 | C25: ='BOQ Summary'!C18 -> TERMITE TREATMENT - SPRAY, PENETRATION COLLARS, BAIT TRAPS | D25: ='BOQ Summary'!D18 -> 0 | E25: ='BOQ Summary'!F18 -> 0 | F25: ='BOQ Summary'!G18 -> 0 | G25: ='BOQ Summary'!H18 -> 0 | H25: ='BOQ Summary'!I18 -> 0 | I25: ='BOQ Summary'!J18 -> 0 | J25: ='BOQ Summary'!K18 -> 0 | K25: =IFERROR(H25/F25,0) -> 0 | L25: =IF(F25=0,"—",IF(I25<=F25,"✔ OK",IF(I25<=F25*1.1,"▲ RISK","✖ OVER"))) -> —
B26: ='BOQ Summary'!B19 -> 010 | C26: ='BOQ Summary'!C19 -> GROUND FLOOR & RAISED PLATFORM FRAMING - TIMBER & HARDWARE | D26: ='BOQ Summary'!D19 -> 0 | E26: ='BOQ Summary'!F19 -> 0 | F26: ='BOQ Summary'!G19 -> 0 | G26: ='BOQ Summary'!H19 -> 0 | H26: ='BOQ Summary'!I19 -> 0 | I26: ='BOQ Summary'!J19 -> 0 | J26: ='BOQ Summary'!K19 -> 0 | K26: =IFERROR(H26/F26,0) -> 0 | L26: =IF(F26=0,"—",IF(I26<=F26,"✔ OK",IF(I26<=F26*1.1,"▲ RISK","✖ OVER"))) -> —
B27: ='BOQ Summary'!B20 -> 011 | C27: ='BOQ Summary'!C20 -> FIRST FLOOR FRAMING - TIMBER & HARDWARE | D27: ='BOQ Summary'!D20 -> 0 | E27: ='BOQ Summary'!F20 -> 0 | F27: ='BOQ Summary'!G20 -> 0 | G27: ='BOQ Summary'!H20 -> 0 | H27: ='BOQ Summary'!I20 -> 0 | I27: ='BOQ Summary'!J20 -> 0 | J27: ='BOQ Summary'!K20 -> 0 | K27: =IFERROR(H27/F27,0) -> 0 | L27: =IF(F27=0,"—",IF(I27<=F27,"✔ OK",IF(I27<=F27*1.1,"▲ RISK","✖ OVER"))) -> —
B28: ='BOQ Summary'!B21 -> 012 | C28: ='BOQ Summary'!C21 -> FRAMING - TIMBER & HARDWARE (MISC) | D28: ='BOQ Summary'!D21 -> 0 | E28: ='BOQ Summary'!F21 -> 0 | F28: ='BOQ Summary'!G21 -> 0 | G28: ='BOQ Summary'!H21 -> 0 | H28: ='BOQ Summary'!I21 -> 0 | I28: ='BOQ Summary'!J21 -> 0 | J28: ='BOQ Summary'!K21 -> 0 | K28: =IFERROR(H28/F28,0) -> 0 | L28: =IF(F28=0,"—",IF(I28<=F28,"✔ OK",IF(I28<=F28*1.1,"▲ RISK","✖ OVER"))) -> —
... B60: ='BOQ Summary'!B53 -> 044 | C60: ='BOQ Summary'!C53 -> PROJECT OVERHEAD COSTS | D60: ='BOQ Summary'!D53 -> 0 | E60: ='BOQ Summary'!F53 -> 0 | F60: ='BOQ Summary'!G53 -> 0 | G60: ='BOQ Summary'!H53 -> 0 | H60: ='BOQ Summary'!I53 -> 0 | I60: ='BOQ Summary'!J53 -> 0 | J60: ='BOQ Summary'!K53 -> 0 | K60: =IFERROR(H60/F60,0) -> 0 | L60: =IF(F60=0,"—",IF(I60<=F60,"✔ OK",IF(I60<=F60*1.1,"▲ RISK","✖ OVER"))) -> —
B61: TOTAL (excl. margin & GST) | D61: =SUM(D17:D60) -> 0 | E61: =SUM(E17:E60) -> 0 | F61: =SUM(F17:F60) -> 0 | G61: =SUM(G17:G60) -> 0 | H61: =SUM(H17:H60) -> 0 | I61: =SUM(I17:I60) -> 0 | J61: =SUM(J17:J60) -> 0

Sheet BOQ Detail
B2: BOQ DETAIL — SUB-LINE ITEM REGISTER
B4: Enter every sub-line item here. CC must match exactly (e.g. "001"). Amount = Qty × Rate (auto). Sub-items roll up to BOQ Summary original budgets.
B6: CC | C6: Sub-Code | D6: Description of Work / Item | E6: Qty | F6: Unit | G6: Rate (excl. GST) ($) | H6: Amount (excl. GST) ($) | I6: Notes
B7: 001 — PRELIMINARY COSTS, CONSULTANT FEES, SITE ESTABLISHMENT
B8: 001 | C8: 001.1 | G8: 0 | H8: =IF(E8="",G8,IF(ISNUMBER(E8),E8*G8,G8)) -> 0
B9: 001 | C9: 001.2 | G9: 0 | H9: =IF(E9="",G9,IF(ISNUMBER(E9),E9*G9,G9)) -> 0
B10: 001 | C10: 001.3 | G10: 0 | H10: =IF(E10="",G10,IF(ISNUMBER(E10),E10*G10,G10)) -> 0
B11: 001 | C11: 001.4 | G11: 0 | H11: =IF(E11="",G11,IF(ISNUMBER(E11),E11*G11,G11)) -> 0
B12: 001 | C12: 001.5 | G12: 0 | H12: =IF(E12="",G12,IF(ISNUMBER(E12),E12*G12,G12)) -> 0
B13: 001 | C13: 001.6 | G13: 0 | H13: =IF(E13="",G13,IF(ISNUMBER(E13),E13*G13,G13)) -> 0
B14: 001 | C14: 001.7 | G14: 0 | H14: =IF(E14="",G14,IF(ISNUMBER(E14),E14*G14,G14)) -> 0
B15: 001 | C15: 001.8 | G15: 0 | H15: =IF(E15="",G15,IF(ISNUMBER(E15),E15*G15,G15)) -> 0
B17: 002 — SITE HIRE ITEMS
B18: 002 | C18: 002.1 | G18: 0 | H18: =IF(E18="",G18,IF(ISNUMBER(E18),E18*G18,G18)) -> 0
B19: 002 | C19: 002.2 | G19: 0 | H19: =IF(E19="",G19,IF(ISNUMBER(E19),E19*G19,G19)) -> 0
B20: 002 | C20: 002.3 | G20: 0 | H20: =IF(E20="",G20,IF(ISNUMBER(E20),E20*G20,G20)) -> 0
B21: 002 | C21: 002.4 | G21: 0 | H21: =IF(E21="",G21,IF(ISNUMBER(E21),E21*G21,G21)) -> 0
B22: 002 | C22: 002.5 | G22: 0 | H22: =IF(E22="",G22,IF(ISNUMBER(E22),E22*G22,G22)) -> 0
B23: 002 | C23: 002.6 | G23: 0 | H23: =IF(E23="",G23,IF(ISNUMBER(E23),E23*G23,G23)) -> 0
B24: 002 | C24: 002.7 | G24: 0 | H24: =IF(E24="",G24,IF(ISNUMBER(E24),E24*G24,G24)) -> 0
B25: 002 | C25: 002.8 | G25: 0 | H25: =IF(E25="",G25,IF(ISNUMBER(E25),E25*G25,G25)) -> 0
B27: 003 — SURVEYING - SET-OUT, TBM, PINS
B28: 003 | C28: 003.1 | G28: 0 | H28: =IF(E28="",G28,IF(ISNUMBER(E28),E28*G28,G28)) -> 0
B29: 003 | C29: 003.2 | G29: 0 | H29: =IF(E29="",G29,IF(ISNUMBER(E29),E29*G29,G29)) -> 0
B30: 003 | C30: 003.3 | G30: 0 | H30: =IF(E30="",G30,IF(ISNUMBER(E30),E30*G30,G30)) -> 0
B31: 003 | C31: 003.4 | G31: 0 | H31: =IF(E31="",G31,IF(ISNUMBER(E31),E31*G31,G31)) -> 0
B32: 003 | C32: 003.5 | G32: 0 | H32: =IF(E32="",G32,IF(ISNUMBER(E32),E32*G32,G32)) -> 0
B33: 003 | C33: 003.6 | G33: 0 | H33: =IF(E33="",G33,IF(ISNUMBER(E33),E33*G33,G33)) -> 0
B34: 003 | C34: 003.7 | G34: 0 | H34: =IF(E34="",G34,IF(ISNUMBER(E34),E34*G34,G34)) -> 0
B35: 003 | C35: 003.8 | G35: 0 | H35: =IF(E35="",G35,IF(ISNUMBER(E35),E35*G35,G35)) -> 0
B37: 004 — STRUCTURAL STEEL - SUPPLY AND INSTALLATION
B38: 004 | C38: 004.1 | G38: 0 | H38: =IF(E38="",G38,IF(ISNUMBER(E38),E38*G38,G38)) -> 0
B39: 004 | C39: 004.2 | G39: 0 | H39: =IF(E39="",G39,IF(ISNUMBER(E39),E39*G39,G39)) -> 0
B40: 004 | C40: 004.3 | G40: 0 | H40: =IF(E40="",G40,IF(ISNUMBER(E40),E40*G40,G40)) -> 0
B41: 004 | C41: 004.4 | G41: 0 | H41: =IF(E41="",G41,IF(ISNUMBER(E41),E41*G41,G41)) -> 0
B42: 004 | C42: 004.5 | G42: 0 | H42: =IF(E42="",G42,IF(ISNUMBER(E42),E42*G42,G42)) -> 0
B43: 004 | C43: 004.6 | G43: 0 | H43: =IF(E43="",G43,IF(ISNUMBER(E43),E43*G43,G43)) -> 0
B44: 004 | C44: 004.7 | G44: 0 | H44: =IF(E44="",G44,IF(ISNUMBER(E44),E44*G44,G44)) -> 0
B45: 004 | C45: 004.8 | G45: 0 | H45: =IF(E45="",G45,IF(ISNUMBER(E45),E45*G45,G45)) -> 0
B47: 005 — STRUCTURAL CONCRETE - FOUNDATIONS, PIERS, SLAB
...

Sheet BOQ Summary
B2: BOQ SUMMARY — COST CODE FINANCIAL TRACKER
B4: Original Budget rolls up automatically from BOQ Detail. Variations, Invoices and POs feed all other columns.
B6: Builder Margin Rate: | C6: GST Rate: | D6: 0.15 | E6: 0.1 | F6: ← Edit rates here
B8: Blue = input | Black = formula | Green = linked from another sheet
B9: CC | C9: Description | D9: Original Budget (from BOQ Detail) ($) | E9: No. of Variations | F9: Approved Variations ($) | G9: Revised Budget ($) | H9: Committed Cost ($) | I9: Actual Cost to Date ($) | J9: Forecast Final Cost ($) | K9: Variance to Budget ($) | L9: Budget Balance ($) | M9: Notes
B10: 001 | C10: PRELIMINARY COSTS, CONSULTANT FEES, SITE ESTABLISHMENT | D10: =SUMIFS('BOQ Detail'!H7:H446,'BOQ Detail'!B7:B446,B10) -> 0 | E10: =COUNTIFS('Variation Register'!$B$6:$B$205,B10,'Variation Register'!$F$6:$F$205,"Approved") -> 0 | F10: =SUMIFS('Variation Register'!$E$6:$E$205,'Variation Register'!$B$6:$B$205,B10,'Variation Register'!$F$6:$F$205,"Approved") -> 0 | G10: =D10+F10 -> 0 | H10: =SUMIFS('PO Register'!$F$6:$F$205,'PO Register'!$B$6:$B$205,B10) -> 0 | I10: =SUMIFS('Invoice Register'!$G$6:$G$405,'Invoice Register'!$B$6:$B$405,B10,'Invoice Register'!$K$6:$K$405,"Paid")+SUMIFS('Invoice Register'!$G$6:$G$405,'Invoice Register'!$B$6:$B$405,B10,'Invoice Register'!$K$6:$K$405,"Approved")+SUMIFS('Site Diary'!$I$6:$I$505,'Site Diary'!$H$6:$H$505,B10) -> 0 | J10: =IF(H10=0,I10,MAX(H10,I10)) -> 0 | K10: =G10-J10 -> 0 | L10: =G10-I10 -> 0
B11: 002 | C11: SITE HIRE ITEMS | D11: =SUMIFS('BOQ Detail'!H7:H446,'BOQ Detail'!B7:B446,B11) -> 0 | E11: =COUNTIFS('Variation Register'!$B$6:$B$205,B11,'Variation Register'!$F$6:$F$205,"Approved") -> 0 | F11: =SUMIFS('Variation Register'!$E$6:$E$205,'Variation Register'!$B$6:$B$205,B11,'Variation Register'!$F$6:$F$205,"Approved") -> 0 | G11: =D11+F11 -> 0 | H11: =SUMIFS('PO Register'!$F$6:$F$205,'PO Register'!$B$6:$B$205,B11) -> 0 | I11: =SUMIFS('Invoice Register'!$G$6:$G$405,'Invoice Register'!$B$6:$B$405,B11,'Invoice Register'!$K$6:$K$405,"Paid")+SUMIFS('Invoice Register'!$G$6:$G$405,'Invoice Register'!$B$6:$B$405,B11,'Invoice Register'!$K$6:$K$405,"Approved")+SUMIFS('Site Diary'!$I$6:$I$505,'Site Diary'!$H$6:$H$505,B11) -> 0 | J11: =IF(H11=0,I11,MAX(H11,I11)) -> 0 | K11: =G11-J11 -> 0 | L11: =G11-I11 -> 0
B12: 003 | C12: SURVEYING - SET-OUT, TBM, PINS | D12: =SUMIFS('BOQ Detail'!H7:H446,'BOQ Detail'!B7:B446,B12) -> 0 | E12: =COUNTIFS('Variation Register'!$B$6:$B$205,B12,'Variation Register'!$F$6:$F$205,"Approved") -> 0 | F12: =SUMIFS('Variation Register'!$E$6:$E$205,'Variation Register'!$B$6:$B$205,B12,'Variation Register'!$F$6:$F$205,"Approved") -> 0 | G12: =D12+F12 -> 0 | H12: =SUMIFS('PO Register'!$F$6:$F$205,'PO Register'!$B$6:$B$205,B12) -> 0 | I12: =SUMIFS('Invoice Register'!$G$6:$G$405,'Invoice Register'!$B$6:$B$405,B12,'Invoice Register'!$K$6:$K$405,"Paid")+SUMIFS('Invoice Register'!$G$6:$G$405,'Invoice Register'!$B$6:$B$405,B12,'Invoice Register'!$K$6:$K$405,"Approved")+SUMIFS('Site Diary'!$I$6:$I$505,'Site Diary'!$H$6:$H$505,B12) -> 0 | J12: =IF(H12=0,I12,MAX(H12,I12)) -> 0 | K12: =G12-J12 -> 0 | L12: =G12-I12 -> 0
B13: 004 | C13: STRUCTURAL STEEL - SUPPLY AND INSTALLATION | D13: =SUMIFS('BOQ Detail'!H7:H446,'BOQ Detail'!B7:B446,B13) -> 0 | E13: =COUNTIFS('Variation Register'!$B$6:$B$205,B13,'Variation Register'!$F$6:$F$205,"Approved") -> 0 | F13: =SUMIFS('Variation Register'!$E$6:$E$205,'Variation Register'!$B$6:$B$205,B13,'Variation Register'!$F$6:$F$205,"Approved") -> 0 | G13: =D13+F13 -> 0 | H13: =SUMIFS('PO Register'!$F$6:$F$205,'PO Register'!$B$6:$B$205,B13) -> 0 | I13: =SUMIFS('Invoice Register'!$G$6:$G$405,'Invoice Register'!$B$6:$B$405,B13,'Invoice Register'!$K$6:$K$405,"Paid")+SUMIFS('Invoice Register'!$G$6:$G$405,'Invoice Register'!$B$6:$B$405,B13,'Invoice Register'!$K$6:$K$405,"Approved")+SUMIFS('Site Diary'!$I$6:$I$505,'Site Diary'!$H$6:$H$505,B13) -> 0 | J13: =IF(H13=0,I13,MAX(H13,I13)) -> 0 | K13: =G13-J13 -> 0 | L13: =G13-I13 -> 0
B14: 005 | C14: STRUCTURAL CONCRETE - FOUNDATIONS, PIERS, SLAB | D14: =SUMIFS('BOQ Detail'!H7:H446,'BOQ Detail'!B7:B446,B14) -> 0 | E14: =COUNTIFS('Variation Register'!$B$6:$B$205,B14,'Variation Register'!$F$6:$F$205,"Approved") -> 0 | F14: =SUMIFS('Variation Register'!$E$6:$E$205,'Variation Register'!$B$6:$B$205,B14,'Variation Register'!$F$6:$F$205,"Approved") -> 0 | G14: =D14+F14 -> 0 | H14: =SUMIFS('PO Register'!$F$6:$F$205,'PO Register'!$B$6:$B$205,B14) -> 0 | I14: =SUMIFS('Invoice Register'!$G$6:$G$405,'Invoice Register'!$B$6:$B$405,B14,'Invoice Register'!$K$6:$K$405,"Paid")+SUMIFS('Invoice Register'!$G$6:$G$405,'Invoice Register'!$B$6:$B$405,B14,'Invoice Register'!$K$6:$K$405,"Approved")+SUMIFS('Site Diary'!$I$6:$I$505,'Site Diary'!$H$6:$H$505,B14) -> 0 | J14: =IF(H14=0,I14,MAX(H14,I14)) -> 0 | K14: =G14-J14 -> 0 | L14: =G14-I14 -> 0
B15: 006 | C15: DRAINAGE PLUMBING - SEPTIC, STORMWATER, AG-DRAINAGE | D15: =SUMIFS('BOQ Detail'!H7:H446,'BOQ Detail'!B7:B446,B15) -> 0 | E15: =COUNTIFS('Variation Register'!$B$6:$B$205,B15,'Variation Register'!$F$6:$F$205,"Approved") -> 0 | F15: =SUMIFS('Variation Register'!$E$6:$E$205,'Variation Register'!$B$6:$B$205,B15,'Variation Register'!$F$6:$F$205,"Approved") -> 0 | G15: =D15+F15 -> 0 | H15: =SUMIFS('PO Register'!$F$6:$F$205,'PO Register'!$B$6:$B$205,B15) -> 0 | I15: =SUMIFS('Invoice Register'!$G$6:$G$405,'Invoice Register'!$B$6:$B$405,B15,'Invoice Register'!$K$6:$K$405,"Paid")+SUMIFS('Invoice Register'!$G$6:$G$405,'Invoice Register'!$B$6:$B$405,B15,'Invoice Register'!$K$6:$K$405,"Approved")+SUMIFS('Site Diary'!$I$6:$I$505,'Site Diary'!$H$6:$H$505,B15) -> 0 | J15: =IF(H15=0,I15,MAX(H15,I15)) -> 0 | K15: =G15-J15 -> 0 | L15: =G15-I15 -> 0
B16: 007 | C16: MEZZANINE & GALLERY / STORAGE FLOOR FRAMING - TIMBER & HARDWARE | D16: =SUMIFS('BOQ Detail'!H7:H446,'BOQ Detail'!B7:B446,B16) -> 0 | E16: =COUNTIFS('Variation Register'!$B$6:$B$205,B16,'Variation Register'!$F$6:$F$205,"Approved") -> 0 | F16: =SUMIFS('Variation Register'!$E$6:$E$205,'Variation Register'!$B$6:$B$205,B16,'Variation Register'!$F$6:$F$205,"Approved") -> 0 | G16: =D16+F16 -> 0 | H16: =SUMIFS('PO Register'!$F$6:$F$205,'PO Register'!$B$6:$B$205,B16) -> 0 | I16: =SUMIFS('Invoice Register'!$G$6:$G$405,'Invoice Register'!$B$6:$B$405,B16,'Invoice Register'!$K$6:$K$405,"Paid")+SUMIFS('Invoice Register'!$G$6:$G$405,'Invoice Register'!$B$6:$B$405,B16,'Invoice Register'!$K$6:$K$405,"Approved")+SUMIFS('Site Diary'!$I$6:$I$505,'Site Diary'!$H$6:$H$505,B16) -> 0 | J16: =IF(H16=0,I16,MAX(H16,I16)) -> 0 | K16: =G16-J16 -> 0 | L16: =G16-I16 -> 0
B17: 008 | C17: CARPENTRY LABOUR - MEZZANINE FLOOR GRADING & LAYING | D17: =SUMIFS('BOQ Detail'!H7:H446,'BOQ Detail'!B7:B446,B17) -> 0 | E17: =COUNTIFS('Variation Register'!$B$6:$B$205,B17,'Variation Register'!$F$6:$F$205,"Approved") -> 0 | F17: =SUMIFS('Variation Register'!$E$6:$E$205,'Variation Register'!$B$6:$B$205,B17,'Variation Register'!$F$6:$F$205,"Approved") -> 0 | G17: =D17+F17 -> 0 | H17: =SUMIFS('PO Register'!$F$6:$F$205,'PO Register'!$B$6:$B$205,B17) -> 0 | I17: =SUMIFS('Invoice Register'!$G$6:$G$405,'Invoice Register'!$B$6:$B$405,B17,'Invoice Register'!$K$6:$K$405,"Paid")+SUMIFS('Invoice Register'!$G$6:$G$405,'Invoice Register'!$B$6:$B$405,B17,'Invoice Register'!$K$6:$K$405,"Approved")+SUMIFS('Site Diary'!$I$6:$I$505,'Site Diary'!$H$6:$H$505,B17) -> 0 | J17: =IF(H17=0,I17,MAX(H17,I17)) -> 0 | K17: =G17-J17 -> 0 | L17: =G17-I17 -> 0
B18: 009 | C18: TERMITE TREATMENT - SPRAY, PENETRATION COLLARS, BAIT TRAPS | D18: =SUMIFS('BOQ Detail'!H7:H446,'BOQ Detail'!B7:B446,B18) -> 0 | E18: =COUNTIFS('Variation Register'!$B$6:$B$205,B18,'Variation Register'!$F$6:$F$205,"Approved") -> 0 | F18: =SUMIFS('Variation Register'!$E$6:$E$205,'Variation Register'!$B$6:$B$205,B18,'Variation Register'!$F$6:$F$205,"Approved") -> 0 | G18: =D18+F18 -> 0 | H18: =SUMIFS('PO Register'!$F$6:$F$205,'PO Register'!$B$6:$B$205,B18) -> 0 | I18: =SUMIFS('Invoice Register'!$G$6:$G$405,'Invoice Register'!$B$6:$B$405,B18,'Invoice Register'!$K$6:$K$405,"Paid")+SUMIFS('Invoice Register'!$G$6:$G$405,'Invoice Register'!$B$6:$B$405,B18,'Invoice Register'!$K$6:$K$405,"Approved")+SUMIFS('Site Diary'!$I$6:$I$505,'Site Diary'!$H$6:$H$505,B18) -> 0 | J18: =IF(H18=0,I18,MAX(H18,I18)) -> 0 | K18: =G18-J18 -> 0 | L18: =G18-I18 -> 0
B19: 010 | C19: GROUND FLOOR & RAISED PLATFORM FRAMING - TIMBER & HARDWARE | D19: =SUMIFS('BOQ Detail'!H7:H446,'BOQ Detail'!B7:B446,B19) -> 0 | E19: =COUNTIFS('Variation Register'!$B$6:$B$205,B19,'Variation Register'!$F$6:$F$205,"Approved") -> 0 | F19: =SUMIFS('Variation Register'!$E$6:$E$205,'Variation Register'!$B$6:$B$205,B19,'Variation Register'!$F$6:$F$205,"Approved") -> 0 | G19: =D19+F19 -> 0 | H19: =SUMIFS('PO Register'!$F$6:$F$205,'PO Register'!$B$6:$B$205,B19) -> 0 | I19: =SUMIFS('Invoice Register'!$G$6:$G$405,'Invoice Register'!$B$6:$B$405,B19,'Invoice Register'!$K$6:$K$405,"Paid")+SUMIFS('Invoice Register'!$G$6:$G$405,'Invoice Register'!$B$6:$B$405,B19,'Invoice Register'!$K$6:$K$405,"Approved")+SUMIFS('Site Diary'!$I$6:$I$505,'Site Diary'!$H$6:$H$505,B19) -> 0 | J19: =IF(H19=0,I19,MAX(H19,I19)) -> 0 | K19: =G19-J19 -> 0 | L19: =G19-I19 -> 0
B20: 011 | C20: FIRST FLOOR FRAMING - TIMBER & HARDWARE | D20: =SUMIFS('BOQ Detail'!H7:H446,'BOQ Detail'!B7:B446,B20) -> 0 | E20: =COUNTIFS('Variation Register'!$B$6:$B$205,B20,'Variation Register'!$F$6:$F$205,"Approved") -> 0 | F20: =SUMIFS('Variation Register'!$E$6:$E$205,'Variation Register'!$B$6:$B$205,B20,'Variation Register'!$F$6:$F$205,"Approved") -> 0 | G20: =D20+F20 -> 0 | H20: =SUMIFS('PO Register'!$F$6:$F$205,'PO Register'!$B$6:$B$205,B20) -> 0 | I20: =SUMIFS('Invoice Register'!$G$6:$G$405,'Invoice Register'!$B$6:$B$405,B20,'Invoice Register'!$K$6:$K$405,"Paid")+SUMIFS('Invoice Register'!$G$6:$G$405,'Invoice Register'!$B$6:$B$405,B20,'Invoice Register'!$K$6:$K$405,"Approved")+SUMIFS('Site Diary'!$I$6:$I$505,'Site Diary'!$H$6:$H$505,B20) -> 0 | J20: =IF(H20=0,I20,MAX(H20,I20)) -> 0 | K20: =G20-J20 -> 0 | L20: =G20-I20 -> 0
B21: 012 | C21: FRAMING - TIMBER & HARDWARE (MISC) | D21: =SUMIFS('BOQ Detail'!H7:H446,'BOQ Detail'!B7:B446,B21) -> 0 | E21: =COUNTIFS('Variation Register'!$B$6:$B$205,B21,'Variation Register'!$F$6:$F$205,"Approved") -> 0 | F21: =SUMIFS('Variation Register'!$E$6:$E$205,'Variation Register'!$B$6:$B$205,B21,'Variation Register'!$F$6:$F$205,"Approved") -> 0 | G21: =D21+F21 -> 0 | H21: =SUMIFS('PO Register'!$F$6:$F$205,'PO Register'!$B$6:$B$205,B21) -> 0 | I21: =SUMIFS('Invoice Register'!$G$6:$G$405,'Invoice Register'!$B$6:$B$405,B21,'Invoice Register'!$K$6:$K$405,"Paid")+SUMIFS('Invoice Register'!$G$6:$G$405,'Invoice Register'!$B$6:$B$405,B21,'Invoice Register'!$K$6:$K$405,"Approved")+SUMIFS('Site Diary'!$I$6:$I$505,'Site Diary'!$H$6:$H$505,B21) -> 0 | J21: =IF(H21=0,I21,MAX(H21,I21)) -> 0 | K21: =G21-J21 -> 0 | L21: =G21-I21 -> 0
B22: 013 | C22: ROOF TRUSSES - TRUSSES, RAFTERS, POSI-TRUSSES | D22: =SUMIFS('BOQ Detail'!H7:H446,'BOQ Detail'!B7:B446,B22) -> 0 | E22: =COUNTIFS('Variation Register'!$B$6:$B$205,B22,'Variation Register'!$F$6:$F$205,"Approved") -> 0 | F22: =SUMIFS('Variation Register'!$E$6:$E$205,'Variation Register'!$B$6:$B$205,B22,'Variation Register'!$F$6:$F$205,"Approved") -> 0 | G22: =D22+F22 -> 0 | H22: =SUMIFS('PO Register'!$F$6:$F$205,'PO Register'!$B$6:$B$205,B22) -> 0 | I22: =SUMIFS('Invoice Register'!$G$6:$G$405,'Invoice Register'!$B$6:$B$405,B22,'Invoice Register'!$K$6:$K$405,"Paid")+SUMIFS('Invoice Register'!$G$6:$G$405,'Invoice Register'!$B$6:$B$405,B22,'Invoice Register'!$K$6:$K$405,"Approved")+SUMIFS('Site Diary'!$I$6:$I$505,'Site Diary'!$H$6:$H$505,B22) -> 0 | J22: =IF(H22=0,I22,MAX(H22,I22)) -> 0 | K22: =G22-J22 -> 0 | L22: =G22-I22 -> 0
B23: 014 | C23: FRAMING - CARPENTRY LABOUR, STRUCTURAL | D23: =SUMIFS('BOQ Detail'!H7:H446,'BOQ Detail'!B7:B446,B23) -> 0 | E23: =COUNTIFS('Variation Register'!$B$6:$B$205,B23,'Variation Register'!$F$6:$F$205,"Approved") -> 0 | F23: =SUMIFS('Variation Register'!$E$6:$E$205,'Variation Register'!$B$6:$B$205,B23,'Variation Register'!$F$6:$F$205,"Approved") -> 0 | G23: =D23+F23 -> 0 | H23: =SUMIFS('PO Register'!$F$6:$F$205,'PO Register'!$B$6:$B$205,B23) -> 0 | I23: =SUMIFS('Invoice Register'!$G$6:$G$405,'Invoice Register'!$B$6:$B$405,B23,'Invoice Register'!$K$6:$K$405,"Paid")+SUMIFS('Invoice Register'!$G$6:$G$405,'Invoice Register'!$B$6:$B$405,B23,'Invoice Register'!$K$6:$K$405,"Approved")+SUMIFS('Site Diary'!$I$6:$I$505,'Site Diary'!$H$6:$H$505,B23) -> 0 | J23: =IF(H23=0,I23,MAX(H23,I23)) -> 0 | K23: =G23-J23 -> 0 | L23: =G23-I23 -> 0
B24: 015 | C24: SHEET-METAL & CUSTOM METAL WORK | D24: =SUMIFS('BOQ Detail'!H7:H446,'BOQ Detail'!B7:B446,B24) -> 0 | E24: =COUNTIFS('Variation Register'!$B$6:$B$205,B24,'Variation Register'!$F$6:$F$205,"Approved") -> 0 | F24: =SUMIFS('Variation Register'!$E$6:$E$205,'Variation Register'!$B$6:$B$205,B24,'Variation Register'!$F$6:$F$205,"Approved") -> 0 | G24: =D24+F24 -> 0 | H24: =SUMIFS('PO Register'!$F$6:$F$205,'PO Register'!$B$6:$B$205,B24) -> 0 | I24: =SUMIFS('Invoice Register'!$G$6:$G$405,'Invoice Register'!$B$6:$B$405,B24,'Invoice Register'!$K$6:$K$405,"Paid")+SUMIFS('Invoice Register'!$G$6:$G$405,'Invoice Register'!$B$6:$B$405,B24,'Invoice Register'!$K$6:$K$405,"Approved")+SUMIFS('Site Diary'!$I$6:$I$505,'Site Diary'!$H$6:$H$505,B24) -> 0 | J24: =IF(H24=0,I24,MAX(H24,I24)) -> 0 | K24: =G24-J24 -> 0 | L24: =G24-I24 -> 0
B25: 016 | C25: WINDOWS & DOORS - INTERNAL | D25: =SUMIFS('BOQ Detail'!H7:H446,'BOQ Detail'!B7:B446,B25) -> 0 | E25: =COUNTIFS('Variation Register'!$B$6:$B$205,B25,'Variation Register'!$F$6:$F$205,"Approved") -> 0 | F25: =SUMIFS('Variation Register'!$E$6:$E$205,'Variation Register'!$B$6:$B$205,B25,'Variation Register'!$F$6:$F$205,"Approved") -> 0 | G25: =D25+F25 -> 0 | H25: =SUMIFS('PO Register'!$F$6:$F$205,'PO Register'!$B$6:$B$205,B25) -> 0 | I25: =SUMIFS('Invoice Register'!$G$6:$G$405,'Invoice Register'!$B$6:$B$405,B25,'Invoice Register'!$K$6:$K$405,"Paid")+SUMIFS('Invoice Register'!$G$6:$G$405,'Invoice Register'!$B$6:$B$405,B25,'Invoice Register'!$K$6:$K$405,"Approved")+SUMIFS('Site Diary'!$I$6:$I$505,'Site Diary'!$H$6:$H$505,B25) -> 0 | J25: =IF(H25=0,I25,MAX(H25,I25)) -> 0 | K25: =G25-J25 -> 0 | L25: =G25-I25 -> 0
B26: 017 | C26: LOCKUP MATERIALS - CLADDING, HARDWARE, FLASHING | D26: =SUMIFS('BOQ Detail'!H7:H446,'BOQ Detail'!B7:B446,B26) -> 0 | E26: =COUNTIFS('Variation Register'!$B$6:$B$205,B26,'Variation Register'!$F$6:$F$205,"Approved") -> 0 | F26: =SUMIFS('Variation Register'!$E$6:$E$205,'Variation Register'!$B$6:$B$205,B26,'Variation Register'!$F$6:$F$205,"Approved") -> 0 | G26: =D26+F26 -> 0 | H26: =SUMIFS('PO Register'!$F$6:$F$205,'PO Register'!$B$6:$B$205,B26) -> 0 | I26: =SUMIFS('Invoice Register'!$G$6:$G$405,'Invoice Register'!$B$6:$B$405,B26,'Invoice Register'!$K$6:$K$405,"Paid")+SUMIFS('Invoice Register'!$G$6:$G$405,'Invoice Register'!$B$6:$B$405,B26,'Invoice Register'!$K$6:$K$405,"Approved")+SUMIFS('Site Diary'!$I$6:$I$505,'Site Diary'!$H$6:$H$505,B26) -> 0 | J26: =IF(H26=0,I26,MAX(H26,I26)) -> 0 | K26: =G26-J26 -> 0 | L26: =G26-I26 -> 0
B27: 018 | C27: LOCKUP CARPENTRY - CLADDING, INT/EXT WORKS | D27: =SUMIFS('BOQ Detail'!H7:H446,'BOQ Detail'!B7:B446,B27) -> 0 | E27: =COUNTIFS('Variation Register'!$B$6:$B$205,B27,'Variation Register'!$F$6:$F$205,"Approved") -> 0 | F27: =SUMIFS('Variation Register'!$E$6:$E$205,'Variation Register'!$B$6:$B$205,B27,'Variation Register'!$F$6:$F$205,"Approved") -> 0 | G27: =D27+F27 -> 0 | H27: =SUMIFS('PO Register'!$F$6:$F$205,'PO Register'!$B$6:$B$205,B27) -> 0 | I27: =SUMIFS('Invoice Register'!$G$6:$G$405,'Invoice Register'!$B$6:$B$405,B27,'Invoice Register'!$K$6:$K$405,"Paid")+SUMIFS('Invoice Register'!$G$6:$G$405,'Invoice Register'!$B$6:$B$405,B27,'Invoice Register'!$K$6:$K$405,"Approved")+SUMIFS('Site Diary'!$I$6:$I$505,'Site Diary'!$H$6:$H$505,B27) -> 0 | J27: =IF(H27=0,I27,MAX(H27,I27)) -> 0 | K27: =G27-J27 -> 0 | L27: =G27-I27 -> 0
B28: 019 | C28: INSULATION - WALL & CEILING INSULATION & BUILDING WRAP | D28: =SUMIFS('BOQ Detail'!H7:H446,'BOQ Detail'!B7:B446,B28) -> 0 | E28: =COUNTIFS('Variation Register'!$B$6:$B$205,B28,'Variation Register'!$F$6:$F$205,"Approved") -> 0 | F28: =SUMIFS('Variation Register'!$E$6:$E$205,'Variation Register'!$B$6:$B$205,B28,'Variation Register'!$F$6:$F$205,"Approved") -> 0 | G28: =D28+F28 -> 0 | H28: =SUMIFS('PO Register'!$F$6:$F$205,'PO Register'!$B$6:$B$205,B28) -> 0 | I28: =SUMIFS('Invoice Register'!$G$6:$G$405,'Invoice Register'!$B$6:$B$405,B28,'Invoice Register'!$K$6:$K$405,"Paid")+SUMIFS('Invoice Register'!$G$6:$G$405,'Invoice Register'!$B$6:$B$405,B28,'Invoice Register'!$K$6:$K$405,"Approved")+SUMIFS('Site Diary'!$I$6:$I$505,'Site Diary'!$H$6:$H$505,B28) -> 0 | J28: =IF(H28=0,I28,MAX(H28,I28)) -> 0 | K28: =G28-J28 -> 0 | L28: =G28-I28 -> 0
B29: 020 | C29: ELECTRICAL - LABOUR & MATERIALS (LIGHT FITTINGS SEPARATE) | D29: =SUMIFS('BOQ Detail'!H7:H446,'BOQ Detail'!B7:B446,B29) -> 0 | E29: =COUNTIFS('Variation Register'!$B$6:$B$205,B29,'Variation Register'!$F$6:$F$205,"Approved") -> 0 | F29: =SUMIFS('Variation Register'!$E$6:$E$205,'Variation Register'!$B$6:$B$205,B29,'Variation Register'!$F$6:$F$205,"Approved") -> 0 | G29: =D29+F29 -> 0 | H29: =SUMIFS('PO Register'!$F$6:$F$205,'PO Register'!$B$6:$B$205,B29) -> 0 | I29: =SUMIFS('Invoice Register'!$G$6:$G$405,'Invoice Register'!$B$6:$B$405,B29,'Invoice Register'!$K$6:$K$405,"Paid")+SUMIFS('Invoice Register'!$G$6:$G$405,'Invoice Register'!$B$6:$B$405,B29,'Invoice Register'!$K$6:$K$405,"Approved")+SUMIFS('Site Diary'!$I$6:$I$505,'Site Diary'!$H$6:$H$505,B29) -> 0 | J29: =IF(H29=0,I29,MAX(H29,I29)) -> 0 | K29: =G29-J29 -> 0 | L29: =G29-I29 -> 0
B30: 021 | C30: HYDRAULIC PLUMBING - GENERAL | D30: =SUMIFS('BOQ Detail'!H7:H446,'BOQ Detail'!B7:B446,B30) -> 0 | E30: =COUNTIFS('Variation Register'!$B$6:$B$205,B30,'Variation Register'!$F$6:$F$205,"Approved") -> 0 | F30: =SUMIFS('Variation Register'!$E$6:$E$205,'Variation Register'!$B$6:$B$205,B30,'Variation Register'!$F$6:$F$205,"Approved") -> 0 | G30: =D30+F30 -> 0 | H30: =SUMIFS('PO Register'!$F$6:$F$205,'PO Register'!$B$6:$B$205,B30) -> 0 | I30: =SUMIFS('Invoice Register'!$G$6:$G$405,'Invoice Register'!$B$6:$B$405,B30,'Invoice Register'!$K$6:$K$405,"Paid")+SUMIFS('Invoice Register'!$G$6:$G$405,'Invoice Register'!$B$6:$B$405,B30,'Invoice Register'!$K$6:$K$405,"Approved")+SUMIFS('Site Diary'!$I$6:$I$505,'Site Diary'!$H$6:$H$505,B30) -> 0 | J30: =IF(H30=0,I30,MAX(H30,I30)) -> 0 | K30: =G30-J30 -> 0 | L30: =G30-I30 -> 0
B31: 022 | C31: HYDRAULIC PLUMBING ITEMS - HWS, SPECIALTY ITEMS | D31: =SUMIFS('BOQ Detail'!H7:H446,'BOQ Detail'!B7:B446,B31) -> 0 | E31: =COUNTIFS('Variation Register'!$B$6:$B$205,B31,'Variation Register'!$F$6:$F$205,"Approved") -> 0 | F31: =SUMIFS('Variation Register'!$E$6:$E$205,'Variation Register'!$B$6:$B$205,B31,'Variation Register'!$F$6:$F$205,"Approved") -> 0 | G31: =D31+F31 -> 0 | H31: =SUMIFS('PO Register'!$F$6:$F$205,'PO Register'!$B$6:$B$205,B31) -> 0 | I31: =SUMIFS('Invoice Register'!$G$6:$G$405,'Invoice Register'!$B$6:$B$405,B31,'Invoice Register'!$K$6:$K$405,"Paid")+SUMIFS('Invoice Register'!$G$6:$G$405,'Invoice Register'!$B$6:$B$405,B31,'Invoice Register'!$K$6:$K$405,"Approved")+SUMIFS('Site Diary'!$I$6:$I$505,'Site Diary'!$H$6:$H$505,B31) -> 0 | J31: =IF(H31=0,I31,MAX(H31,I31)) -> 0 | K31: =G31-J31 -> 0 | L31: =G31-I31 -> 0
B32: 023 | C32: MECHANICAL PLUMBING AND HVAC | D32: =SUMIFS('BOQ Detail'!H7:H446,'BOQ Detail'!B7:B446,B32) -> 0 | E32: =COUNTIFS('Variation Register'!$B$6:$B$205,B32,'Variation Register'!$F$6:$F$205,"Approved") -> 0 | F32: =SUMIFS('Variation Register'!$E$6:$E$205,'Variation Register'!$B$6:$B$205,B32,'Variation Register'!$F$6:$F$205,"Approved") -> 0 | G32: =D32+F32 -> 0 | H32: =SUMIFS('PO Register'!$F$6:$F$205,'PO Register'!$B$6:$B$205,B32) -> 0 | I32: =SUMIFS('Invoice Register'!$G$6:$G$405,'Invoice Register'!$B$6:$B$405,B32,'Invoice Register'!$K$6:$K$405,"Paid")+SUMIFS('Invoice Register'!$G$6:$G$405,'Invoice Register'!$B$6:$B$405,B32,'Invoice Register'!$K$6:$K$405,"Approved")+SUMIFS('Site Diary'!$I$6:$I$505,'Site Diary'!$H$6:$H$505,B32) -> 0 | J32: =IF(H32=0,I32,MAX(H32,I32)) -> 0 | K32: =G32-J32 -> 0 | L32: =G32-I32 -> 0
B33: 024 | C33: DECKING - FRAMING & HARDWARE | D33: =SUMIFS('BOQ Detail'!H7:H446,'BOQ Detail'!B7:B446,B33) -> 0 | E33: =COUNTIFS('Variation Register'!$B$6:$B$205,B33,'Variation Register'!$F$6:$F$205,"Approved") -> 0 | F33: =SUMIFS('Variation Register'!$E$6:$E$205,'Variation Register'!$B$6:$B$205,B33,'Variation Register'!$F$6:$F$205,"Approved") -> 0 | G33: =D33+F33 -> 0 | H33: =SUMIFS('PO Register'!$F$6:$F$205,'PO Register'!$B$6:$B$205,B33) -> 0 | I33: =SUMIFS('Invoice Register'!$G$6:$G$405,'Invoice Register'!$B$6:$B$405,B33,'Invoice Register'!$K$6:$K$405,"Paid")+SUMIFS('Invoice Register'!$G$6:$G$405,'Invoice Register'!$B$6:$B$405,B33,'Invoice Register'!$K$6:$K$405,"Approved")+SUMIFS('Site Diary'!$I$6:$I$505,'Site Diary'!$H$6:$H$505,B33) -> 0 | J33: =IF(H33=0,I33,MAX(H33,I33)) -> 0 | K33: =G33-J33 -> 0 | L33: =G33-I33 -> 0
B34: 025 | C34: DECKING AND SUB-FLOOR FRAMING MATERIALS | D34: =SUMIFS('BOQ Detail'!H7:H446,'BOQ Detail'!B7:B446,B34) -> 0 | E34: =COUNTIFS('Variation Register'!$B$6:$B$205,B34,'Variation Register'!$F$6:$F$205,"Approved") -> 0 | F34: =SUMIFS('Variation Register'!$E$6:$E$205,'Variation Register'!$B$6:$B$205,B34,'Variation Register'!$F$6:$F$205,"Approved") -> 0 | G34: =D34+F34 -> 0 | H34: =SUMIFS('PO Register'!$F$6:$F$205,'PO Register'!$B$6:$B$205,B34) -> 0 | I34: =SUMIFS('Invoice Register'!$G$6:$G$405,'Invoice Register'!$B$6:$B$405,B34,'Invoice Register'!$K$6:$K$405,"Paid")+SUMIFS('Invoice Register'!$G$6:$G$405,'Invoice Register'!$B$6:$B$405,B34,'Invoice Register'!$K$6:$K$405,"Approved")+SUMIFS('Site Diary'!$I$6:$I$505,'Site Diary'!$H$6:$H$505,B34) -> 0 | J34: =IF(H34=0,I34,MAX(H34,I34)) -> 0 | K34: =G34-J34 -> 0 | L34: =G34-I34 -> 0
B35: 026 | C35: INTERNAL WALL & CEILING LINING - GYROCK, PLYWOOD, OTHER | D35: =SUMIFS('BOQ Detail'!H7:H446,'BOQ Detail'!B7:B446,B35) -> 0 | E35: =COUNTIFS('Variation Register'!$B$6:$B$205,B35,'Variation Register'!$F$6:$F$205,"Approved") -> 0 | F35: =SUMIFS('Variation Register'!$E$6:$E$205,'Variation Register'!$B$6:$B$205,B35,'Variation Register'!$F$6:$F$205,"Approved") -> 0 | G35: =D35+F35 -> 0 | H35: =SUMIFS('PO Register'!$F$6:$F$205,'PO Register'!$B$6:$B$205,B35) -> 0 | I35: =SUMIFS('Invoice Register'!$G$6:$G$405,'Invoice Register'!$B$6:$B$405,B35,'Invoice Register'!$K$6:$K$405,"Paid")+SUMIFS('Invoice Register'!$G$6:$G$405,'Invoice Register'!$B$6:$B$405,B35,'Invoice Register'!$K$6:$K$405,"Approved")+SUMIFS('Site Diary'!$I$6:$I$505,'Site Diary'!$H$6:$H$505,B35) -> 0 | J35: =IF(H35=0,I35,MAX(H35,I35)) -> 0 | K35: =G35-J35 -> 0 | L35: =G35-I35 -> 0
B36: 027 | C36: JOINERY - KITCHEN, BATHROOM, LAUNDRY | D36: =SUMIFS('BOQ Detail'!H7:H446,'BOQ Detail'!B7:B446,B36) -> 0 | E36: =COUNTIFS('Variation Register'!$B$6:$B$205,B36,'Variation Register'!$F$6:$F$205,"Approved") -> 0 | F36: =SUMIFS('Variation Register'!$E$6:$E$205,'Variation Register'!$B$6:$B$205,B36,'Variation Register'!$F$6:$F$205,"Approved") -> 0 | G36: =D36+F36 -> 0 | H36: =SUMIFS('PO Register'!$F$6:$F$205,'PO Register'!$B$6:$B$205,B36) -> 0 | I36: =SUMIFS('Invoice Register'!$G$6:$G$405,'Invoice Register'!$B$6:$B$405,B36,'Invoice Register'!$K$6:$K$405,"Paid")+SUMIFS('Invoice Register'!$G$6:$G$405,'Invoice Register'!$B$6:$B$405,B36,'Invoice Register'!$K$6:$K$405,"Approved")+SUMIFS('Site Diary'!$I$6:$I$505,'Site Diary'!$H$6:$H$505,B36) -> 0 | J36: =IF(H36=0,I36,MAX(H36,I36)) -> 0 | K36: =G36-J36 -> 0 | L36: =G36-I36 -> 0
B37: 028 | C37: FINISH CARPENTRY - INTERNAL FINISHING AND DETAIL WORKS | D37: =SUMIFS('BOQ Detail'!H7:H446,'BOQ Detail'!B7:B446,B37) -> 0 | E37: =COUNTIFS('Variation Register'!$B$6:$B$205,B37,'Variation Register'!$F$6:$F$205,"Approved") -> 0 | F37: =SUMIFS('Variation Register'!$E$6:$E$205,'Variation Register'!$B$6:$B$205,B37,'Variation Register'!$F$6:$F$205,"Approved") -> 0 | G37: =D37+F37 -> 0 | H37: =SUMIFS('PO Register'!$F$6:$F$205,'PO Register'!$B$6:$B$205,B37) -> 0 | I37: =SUMIFS('Invoice Register'!$G$6:$G$405,'Invoice Register'!$B$6:$B$405,B37,'Invoice Register'!$K$6:$K$405,"Paid")+SUMIFS('Invoice Register'!$G$6:$G$405,'Invoice Register'!$B$6:$B$405,B37,'Invoice Register'!$K$6:$K$405,"Approved")+SUMIFS('Site Diary'!$I$6:$I$505,'Site Diary'!$H$6:$H$505,B37) -> 0 | J37: =IF(H37=0,I37,MAX(H37,I37)) -> 0 | K37: =G37-J37 -> 0 | L37: =G37-I37 -> 0
B38: 029 | C38: WATERPROOFING & SCREED BEDS | D38: =SUMIFS('BOQ Detail'!H7:H446,'BOQ Detail'!B7:B446,B38) -> 0 | E38: =COUNTIFS('Variation Register'!$B$6:$B$205,B38,'Variation Register'!$F$6:$F$205,"Approved") -> 0 | F38: =SUMIFS('Variation Register'!$E$6:$E$205,'Variation Register'!$B$6:$B$205,B38,'Variation Register'!$F$6:$F$205,"Approved") -> 0 | G38: =D38+F38 -> 0 | H38: =SUMIFS('PO Register'!$F$6:$F$205,'PO Register'!$B$6:$B$205,B38) -> 0 | I38: =SUMIFS('Invoice Register'!$G$6:$G$405,'Invoice Register'!$B$6:$B$405,B38,'Invoice Register'!$K$6:$K$405,"Paid")+SUMIFS('Invoice Register'!$G$6:$G$405,'Invoice Register'!$B$6:$B$405,B38,'Invoice Register'!$K$6:$K$405,"Approved")+SUMIFS('Site Diary'!$I$6:$I$505,'Site Diary'!$H$6:$H$505,B38) -> 0 | J38: =IF(H38=0,I38,MAX(H38,I38)) -> 0 | K38: =G38-J38 -> 0 | L38: =G38-I38 -> 0
B39: 030 | C39: TILE SUPPLY ALLOWANCE | D39: =SUMIFS('BOQ Detail'!H7:H446,'BOQ Detail'!B7:B446,B39) -> 0 | E39: =COUNTIFS('Variation Register'!$B$6:$B$205,B39,'Variation Register'!$F$6:$F$205,"Approved") -> 0 | F39: =SUMIFS('Variation Register'!$E$6:$E$205,'Variation Register'!$B$6:$B$205,B39,'Variation Register'!$F$6:$F$205,"Approved") -> 0 | G39: =D39+F39 -> 0 | H39: =SUMIFS('PO Register'!$F$6:$F$205,'PO Register'!$B$6:$B$205,B39) -> 0 | I39: =SUMIFS('Invoice Register'!$G$6:$G$405,'Invoice Register'!$B$6:$B$405,B39,'Invoice Register'!$K$6:$K$405,"Paid")+SUMIFS('Invoice Register'!$G$6:$G$405,'Invoice Register'!$B$6:$B$405,B39,'Invoice Register'!$K$6:$K$405,"Approved")+SUMIFS('Site Diary'!$I$6:$I$505,'Site Diary'!$H$6:$H$505,B39) -> 0 | J39: =IF(H39=0,I39,MAX(H39,I39)) -> 0 | K39: =G39-J39 -> 0 | L39: =G39-I39 -> 0
B40: 031 | C40: TILING LABOUR | D40: =SUMIFS('BOQ Detail'!H7:H446,'BOQ Detail'!B7:B446,B40) -> 0 | E40: =COUNTIFS('Variation Register'!$B$6:$B$205,B40,'Variation Register'!$F$6:$F$205,"Approved") -> 0 | F40: =SUMIFS('Variation Register'!$E$6:$E$205,'Variation Register'!$B$6:$B$205,B40,'Variation Register'!$F$6:$F$205,"Approved") -> 0 | G40: =D40+F40 -> 0 | H40: =SUMIFS('PO Register'!$F$6:$F$205,'PO Register'!$B$6:$B$205,B40) -> 0 | I40: =SUMIFS('Invoice Register'!$G$6:$G$405,'Invoice Register'!$B$6:$B$405,B40,'Invoice Register'!$K$6:$K$405,"Paid")+SUMIFS('Invoice Register'!$G$6:$G$405,'Invoice Register'!$B$6:$B$405,B40,'Invoice Register'!$K$6:$K$405,"Approved")+SUMIFS('Site Diary'!$I$6:$I$505,'Site Diary'!$H$6:$H$505,B40) -> 0 | J40: =IF(H40=0,I40,MAX(H40,I40)) -> 0 | K40: =G40-J40 -> 0 | L40: =G40-I40 -> 0
B41: 032 | C41: TIMBER FLOORING - SUPPLY & INSTALLATION | D41: =SUMIFS('BOQ Detail'!H7:H446,'BOQ Detail'!B7:B446,B41) -> 0 | E41: =COUNTIFS('Variation Register'!$B$6:$B$205,B41,'Variation Register'!$F$6:$F$205,"Approved") -> 0 | F41: =SUMIFS('Variation Register'!$E$6:$E$205,'Variation Register'!$B$6:$B$205,B41,'Variation Register'!$F$6:$F$205,"Approved") -> 0 | G41: =D41+F41 -> 0 | H41: =SUMIFS('PO Register'!$F$6:$F$205,'PO Register'!$B$6:$B$205,B41) -> 0 | I41: =SUMIFS('Invoice Register'!$G$6:$G$405,'Invoice Register'!$B$6:$B$405,B41,'Invoice Register'!$K$6:$K$405,"Paid")+SUMIFS('Invoice Register'!$G$6:$G$405,'Invoice Register'!$B$6:$B$405,B41,'Invoice Register'!$K$6:$K$405,"Approved")+SUMIFS('Site Diary'!$I$6:$I$505,'Site Diary'!$H$6:$H$505,B41) -> 0 | J41: =IF(H41=0,I41,MAX(H41,I41)) -> 0 | K41: =G41-J41 -> 0 | L41: =G41-I41 -> 0
B42: 033 | C42: FLOOR FINISHING - SANDING & POLISHING | D42: =SUMIFS('BOQ Detail'!H7:H446,'BOQ Detail'!B7:B446,B42) -> 0 | E42: =COUNTIFS('Variation Register'!$B$6:$B$205,B42,'Variation Register'!$F$6:$F$205,"Approved") -> 0 | F42: =SUMIFS('Variation Register'!$E$6:$E$205,'Variation Register'!$B$6:$B$205,B42,'Variation Register'!$F$6:$F$205,"Approved") -> 0 | G42: =D42+F42 -> 0 | H42: =SUMIFS('PO Register'!$F$6:$F$205,'PO Register'!$B$6:$B$205,B42) -> 0 | I42: =SUMIFS('Invoice Register'!$G$6:$G$405,'Invoice Register'!$B$6:$B$405,B42,'Invoice Register'!$K$6:$K$405,"Paid")+SUMIFS('Invoice Register'!$G$6:$G$405,'Invoice Register'!$B$6:$B$405,B42,'Invoice Register'!$K$6:$K$405,"Approved")+SUMIFS('Site Diary'!$I$6:$I$505,'Site Diary'!$H$6:$H$505,B42) -> 0 | J42: =IF(H42=0,I42,MAX(H42,I42)) -> 0 | K42: =G42-J42 -> 0 | L42: =G42-I42 -> 0
B43: 034 | C43: PAINTING - INTERNAL & EXTERNAL | D43: =SUMIFS('BOQ Detail'!H7:H446,'BOQ Detail'!B7:B446,B43) -> 0 | E43: =COUNTIFS('Variation Register'!$B$6:$B$205,B43,'Variation Register'!$F$6:$F$205,"Approved") -> 0 | F43: =SUMIFS('Variation Register'!$E$6:$E$205,'Variation Register'!$B$6:$B$205,B43,'Variation Register'!$F$6:$F$205,"Approved") -> 0 | G43: =D43+F43 -> 0 | H43: =SUMIFS('PO Register'!$F$6:$F$205,'PO Register'!$B$6:$B$205,B43) -> 0 | I43: =SUMIFS('Invoice Register'!$G$6:$G$405,'Invoice Register'!$B$6:$B$405,B43,'Invoice Register'!$K$6:$K$405,"Paid")+SUMIFS('Invoice Register'!$G$6:$G$405,'Invoice Register'!$B$6:$B$405,B43,'Invoice Register'!$K$6:$K$405,"Approved")+SUMIFS('Site Diary'!$I$6:$I$505,'Site Diary'!$H$6:$H$505,B43) -> 0 | J43: =IF(H43=0,I43,MAX(H43,I43)) -> 0 | K43: =G43-J43 -> 0 | L43: =G43-I43 -> 0
B44: 035 | C44: RENDER AND MICRO-CEMENT - INTERNAL & EXTERNAL | D44: =SUMIFS('BOQ Detail'!H7:H446,'BOQ Detail'!B7:B446,B44) -> 0 | E44: =COUNTIFS('Variation Register'!$B$6:$B$205,B44,'Variation Register'!$F$6:$F$205,"Approved") -> 0 | F44: =SUMIFS('Variation Register'!$E$6:$E$205,'Variation Register'!$B$6:$B$205,B44,'Variation Register'!$F$6:$F$205,"Approved") -> 0 | G44: =D44+F44 -> 0 | H44: =SUMIFS('PO Register'!$F$6:$F$205,'PO Register'!$B$6:$B$205,B44) -> 0 | I44: =SUMIFS('Invoice Register'!$G$6:$G$405,'Invoice Register'!$B$6:$B$405,B44,'Invoice Register'!$K$6:$K$405,"Paid")+SUMIFS('Invoice Register'!$G$6:$G$405,'Invoice Register'!$B$6:$B$405,B44,'Invoice Register'!$K$6:$K$405,"Approved")+SUMIFS('Site Diary'!$I$6:$I$505,'Site Diary'!$H$6:$H$505,B44) -> 0 | J44: =IF(H44=0,I44,MAX(H44,I44)) -> 0 | K44: =G44-J44 -> 0 | L44: =G44-I44 -> 0
...

Sheet Variation Register
B2: VARIATION REGISTER — FORMAL APPROVAL LOG
B4: Status = "Approved" | "Pending" | "Rejected". Only APPROVED variations update the Revised Budget in BOQ Summary.
B5: CC | C5: VO No. | D5: Description of Variation | E5: Amount (excl. GST) ($) | F5: Status | G5: Submitted By | H5: Date Submitted | I5: Date Approved | J5: Approved By | K5: Notes
E6: 0
E7: 0
E8: 0
E9: 0
E10: 0
E11: 0
E12: 0
E13: 0
E14: 0
E15: 0
E16: 0
E17: 0
... E205: 0
B206: TOTAL APPROVED VARIATIONS | E206: =SUMIF(F6:F205,"Approved",E6:E205) -> 0

Sheet Invoice Register
B2: INVOICE REGISTER — CONTRACTOR & SUPPLIER INVOICES
B4: Status = "Paid" | "Approved" | "Pending" | "Disputed". Paid and Approved invoices draw down Actual Cost to Date automatically.
B5: CC | C5: Invoice No. | D5: Contractor / Supplier | E5: PO / Contract Ref. | F5: Invoice Date | G5: Invoice Amt (excl. GST) ($) | H5: GST ($) | I5: Total Invoice (incl. GST) ($) | J5: Due Date | K5: Status | L5: Date Paid | M5: Retention Held ($) | N5: Progress Claim No.
G6: 0 | H6: =IF(G6=0,"",G6*0.1) | I6: =IF(G6=0,"",G6*1.1) | M6: 0
G7: 0 | H7: =IF(G7=0,"",G7*0.1) | I7: =IF(G7=0,"",G7*1.1) | M7: 0
G8: 0 | H8: =IF(G8=0,"",G8*0.1) | I8: =IF(G8=0,"",G8*1.1) | M8: 0
G9: 0 | H9: =IF(G9=0,"",G9*0.1) | I9: =IF(G9=0,"",G9*1.1) | M9: 0
G10: 0 | H10: =IF(G10=0,"",G10*0.1) | I10: =IF(G10=0,"",G10*1.1) | M10: 0
G11: 0 | H11: =IF(G11=0,"",G11*0.1) | I11: =IF(G11=0,"",G11*1.1) | M11: 0
G12: 0 | H12: =IF(G12=0,"",G12*0.1) | I12: =IF(G12=0,"",G12*1.1) | M12: 0
G13: 0 | H13: =IF(G13=0,"",G13*0.1) | I13: =IF(G13=0,"",G13*1.1) | M13: 0
G14: 0 | H14: =IF(G14=0,"",G14*0.1) | I14: =IF(G14=0,"",G14*1.1) | M14: 0
G15: 0 | H15: =IF(G15=0,"",G15*0.1) | I15: =IF(G15=0,"",G15*1.1) | M15: 0
G16: 0 | H16: =IF(G16=0,"",G16*0.1) | I16: =IF(G16=0,"",G16*1.1) | M16: 0
G17: 0 | H17: =IF(G17=0,"",G17*0.1) | I17: =IF(G17=0,"",G17*1.1) | M17: 0
... G405: 0 | H405: =IF(G405=0,"",G405*0.1) | I405: =IF(G405=0,"",G405*1.1) | M405: 0
B406: TOTALS | G406: =SUM(G6:G405) -> 0 | H406: =SUM(H6:H405) -> 0 | I406: =SUM(I6:I405) -> 0 | M406: =SUM(M6:M405) -> 0

Sheet Progress Claims
B2: PROGRESS CLAIMS REGISTER
B4: Track formal progress claims per contractor. Link to invoices via Progress Claim No. in the Invoice Register.
B5: CC | C5: Contractor | D5: Description of Claim | E5: Claim No. | F5: Claim Date | G5: Claim Amt (excl. GST) ($) | H5: GST ($) | I5: Total Claim (incl. GST) ($) | J5: Certified Amt ($) | K5: Status | L5: Date Certified
G6: 0 | H6: =IF(G6=0,"",G6*0.1) | I6: =IF(G6=0,"",G6*1.1) | J6: 0
G7: 0 | H7: =IF(G7=0,"",G7*0.1) | I7: =IF(G7=0,"",G7*1.1) | J7: 0
G8: 0 | H8: =IF(G8=0,"",G8*0.1) | I8: =IF(G8=0,"",G8*1.1) | J8: 0
G9: 0 | H9: =IF(G9=0,"",G9*0.1) | I9: =IF(G9=0,"",G9*1.1) | J9: 0
G10: 0 | H10: =IF(G10=0,"",G10*0.1) | I10: =IF(G10=0,"",G10*1.1) | J10: 0
G11: 0 | H11: =IF(G11=0,"",G11*0.1) | I11: =IF(G11=0,"",G11*1.1) | J11: 0
G12: 0 | H12: =IF(G12=0,"",G12*0.1) | I12: =IF(G12=0,"",G12*1.1) | J12: 0
G13: 0 | H13: =IF(G13=0,"",G13*0.1) | I13: =IF(G13=0,"",G13*1.1) | J13: 0
G14: 0 | H14: =IF(G14=0,"",G14*0.1) | I14: =IF(G14=0,"",G14*1.1) | J14: 0
G15: 0 | H15: =IF(G15=0,"",G15*0.1) | I15: =IF(G15=0,"",G15*1.1) | J15: 0
G16: 0 | H16: =IF(G16=0,"",G16*0.1) | I16: =IF(G16=0,"",G16*1.1) | J16: 0
G17: 0 | H17: =IF(G17=0,"",G17*0.1) | I17: =IF(G17=0,"",G17*1.1) | J17: 0
... G205: 0 | H205: =IF(G205=0,"",G205*0.1) | I205: =IF(G205=0,"",G205*1.1) | J205: 0
B206: TOTALS | G206: =SUM(G6:G205) -> 0 | H206: =SUM(H6:H205) -> 0 | I206: =SUM(I6:I205) -> 0 | J206: =SUM(J6:J205) -> 0

Sheet PO Register
B2: PURCHASE ORDER REGISTER — COMMITTED COSTS
B4: PO Value feeds Committed Cost in BOQ Summary. Remaining Commitment = PO Value minus invoiced-to-date.
B5: CC | C5: PO / Contract No. | D5: Contractor / Supplier | E5: PO Date | F5: PO Value (excl. GST) ($) | G5: Invoiced to Date ($) | H5: Remaining Commitment ($) | I5: Status | J5: Expected Completion | K5: Notes
F6: 0 | G6: =IF(F6=0,"",SUMIFS('Invoice Register'!$G$6:$G$405,'Invoice Register'!$B$6:$B$405,B6,'Invoice Register'!$K$6:$K$405,"Paid")+SUMIFS('Invoice Register'!$G$6:$G$405,'Invoice Register'!$B$6:$B$405,B6,'Invoice Register'!$K$6:$K$405,"Approved")) | H6: =IF(F6=0,"",MAX(0,F6-G6))
F7: 0 | G7: =IF(F7=0,"",SUMIFS('Invoice Register'!$G$6:$G$405,'Invoice Register'!$B$6:$B$405,B7,'Invoice Register'!$K$6:$K$405,"Paid")+SUMIFS('Invoice Register'!$G$6:$G$405,'Invoice Register'!$B$6:$B$405,B7,'Invoice Register'!$K$6:$K$405,"Approved")) | H7: =IF(F7=0,"",MAX(0,F7-G7))
F8: 0 | G8: =IF(F8=0,"",SUMIFS('Invoice Register'!$G$6:$G$405,'Invoice Register'!$B$6:$B$405,B8,'Invoice Register'!$K$6:$K$405,"Paid")+SUMIFS('Invoice Register'!$G$6:$G$405,'Invoice Register'!$B$6:$B$405,B8,'Invoice Register'!$K$6:$K$405,"Approved")) | H8: =IF(F8=0,"",MAX(0,F8-G8))
F9: 0 | G9: =IF(F9=0,"",SUMIFS('Invoice Register'!$G$6:$G$405,'Invoice Register'!$B$6:$B$405,B9,'Invoice Register'!$K$6:$K$405,"Paid")+SUMIFS('Invoice Register'!$G$6:$G$405,'Invoice Register'!$B$6:$B$405,B9,'Invoice Register'!$K$6:$K$405,"Approved")) | H9: =IF(F9=0,"",MAX(0,F9-G9))
F10: 0 | G10: =IF(F10=0,"",SUMIFS('Invoice Register'!$G$6:$G$405,'Invoice Register'!$B$6:$B$405,B10,'Invoice Register'!$K$6:$K$405,"Paid")+SUMIFS('Invoice Register'!$G$6:$G$405,'Invoice Register'!$B$6:$B$405,B10,'Invoice Register'!$K$6:$K$405,"Approved")) | H10: =IF(F10=0,"",MAX(0,F10-G10))
F11: 0 | G11: =IF(F11=0,"",SUMIFS('Invoice Register'!$G$6:$G$405,'Invoice Register'!$B$6:$B$405,B11,'Invoice Register'!$K$6:$K$405,"Paid")+SUMIFS('Invoice Register'!$G$6:$G$405,'Invoice Register'!$B$6:$B$405,B11,'Invoice Register'!$K$6:$K$405,"Approved")) | H11: =IF(F11=0,"",MAX(0,F11-G11))
F12: 0 | G12: =IF(F12=0,"",SUMIFS('Invoice Register'!$G$6:$G$405,'Invoice Register'!$B$6:$B$405,B12,'Invoice Register'!$K$6:$K$405,"Paid")+SUMIFS('Invoice Register'!$G$6:$G$405,'Invoice Register'!$B$6:$B$405,B12,'Invoice Register'!$K$6:$K$405,"Approved")) | H12: =IF(F12=0,"",MAX(0,F12-G12))
F13: 0 | G13: =IF(F13=0,"",SUMIFS('Invoice Register'!$G$6:$G$405,'Invoice Register'!$B$6:$B$405,B13,'Invoice Register'!$K$6:$K$405,"Paid")+SUMIFS('Invoice Register'!$G$6:$G$405,'Invoice Register'!$B$6:$B$405,B13,'Invoice Register'!$K$6:$K$405,"Approved")) | H13: =IF(F13=0,"",MAX(0,F13-G13))
F14: 0 | G14: =IF(F14=0,"",SUMIFS('Invoice Register'!$G$6:$G$405,'Invoice Register'!$B$6:$B$405,B14,'Invoice Register'!$K$6:$K$405,"Paid")+SUMIFS('Invoice Register'!$G$6:$G$405,'Invoice Register'!$B$6:$B$405,B14,'Invoice Register'!$K$6:$K$405,"Approved")) | H14: =IF(F14=0,"",MAX(0,F14-G14))
F15: 0 | G15: =IF(F15=0,"",SUMIFS('Invoice Register'!$G$6:$G$405,'Invoice Register'!$B$6:$B$405,B15,'Invoice Register'!$K$6:$K$405,"Paid")+SUMIFS('Invoice Register'!$G$6:$G$405,'Invoice Register'!$B$6:$B$405,B15,'Invoice Register'!$K$6:$K$405,"Approved")) | H15: =IF(F15=0,"",MAX(0,F15-G15))
F16: 0 | G16: =IF(F16=0,"",SUMIFS('Invoice Register'!$G$6:$G$405,'Invoice Register'!$B$6:$B$405,B16,'Invoice Register'!$K$6:$K$405,"Paid")+SUMIFS('Invoice Register'!$G$6:$G$405,'Invoice Register'!$B$6:$B$405,B16,'Invoice Register'!$K$6:$K$405,"Approved")) | H16: =IF(F16=0,"",MAX(0,F16-G16))
F17: 0 | G17: =IF(F17=0,"",SUMIFS('Invoice Register'!$G$6:$G$405,'Invoice Register'!$B$6:$B$405,B17,'Invoice Register'!$K$6:$K$405,"Paid")+SUMIFS('Invoice Register'!$G$6:$G$405,'Invoice Register'!$B$6:$B$405,B17,'Invoice Register'!$K$6:$K$405,"Approved")) | H17: =IF(F17=0,"",MAX(0,F17-G17))
... F205: 0 | G205: =IF(F205=0,"",SUMIFS('Invoice Register'!$G$6:$G$405,'Invoice Register'!$B$6:$B$405,B205,'Invoice Register'!$K$6:$K$405,"Paid")+SUMIFS('Invoice Register'!$G$6:$G$405,'Invoice Register'!$B$6:$B$405,B205,'Invoice Register'!$K$6:$K$405,"Approved")) | H205: =IF(F205=0,"",MAX(0,F205-G205))
B206: TOTALS | F206: =SUM(F6:F205) -> 0 | G206: =SUM(G6:G205) -> 0 | H206: =SUM(H6:H205) -> 0

Sheet Cash Flow Forecast
B2: CASH FLOW FORECAST — MONTHLY EXPENDITURE
B4: Enter forecast spend per cost code per month (excl. GST). Relabel Month 1–12 with actual month names in row 6. Total Forecast must not exceed the Revised Budget.
B6: CC | C6: Description | D6: Month 1 | E6: Month 2 | F6: Month 3 | G6: Month 4 | H6: Month 5 | I6: Month 6 | J6: Month 7 | K6: Month 8 | L6: Month 9 | M6: Month 10 | N6: Month 11 | O6: Month 12 | P6: TOTAL FORECAST ($) | Q6: REVISED BUDGET ($)
B7: ='BOQ Summary'!B10 -> 001 | C7: ='BOQ Summary'!C10 -> PRELIMINARY COSTS, CONSULTANT FEES, SITE ESTABLISHMENT | D7: 0 | E7: 0 | F7: 0 | G7: 0 | H7: 0 | I7: 0 | J7: 0 | K7: 0 | L7: 0 | M7: 0 | N7: 0 | O7: 0 | P7: =SUM(D7:O7) -> 0 | Q7: ='BOQ Summary'!G10 -> 0
B8: ='BOQ Summary'!B11 -> 002 | C8: ='BOQ Summary'!C11 -> SITE HIRE ITEMS | D8: 0 | E8: 0 | F8: 0 | G8: 0 | H8: 0 | I8: 0 | J8: 0 | K8: 0 | L8: 0 | M8: 0 | N8: 0 | O8: 0 | P8: =SUM(D8:O8) -> 0 | Q8: ='BOQ Summary'!G11 -> 0
B9: ='BOQ Summary'!B12 -> 003 | C9: ='BOQ Summary'!C12 -> SURVEYING - SET-OUT, TBM, PINS | D9: 0 | E9: 0 | F9: 0 | G9: 0 | H9: 0 | I9: 0 | J9: 0 | K9: 0 | L9: 0 | M9: 0 | N9: 0 | O9: 0 | P9: =SUM(D9:O9) -> 0 | Q9: ='BOQ Summary'!G12 -> 0
B10: ='BOQ Summary'!B13 -> 004 | C10: ='BOQ Summary'!C13 -> STRUCTURAL STEEL - SUPPLY AND INSTALLATION | D10: 0 | E10: 0 | F10: 0 | G10: 0 | H10: 0 | I10: 0 | J10: 0 | K10: 0 | L10: 0 | M10: 0 | N10: 0 | O10: 0 | P10: =SUM(D10:O10) -> 0 | Q10: ='BOQ Summary'!G13 -> 0
B11: ='BOQ Summary'!B14 -> 005 | C11: ='BOQ Summary'!C14 -> STRUCTURAL CONCRETE - FOUNDATIONS, PIERS, SLAB | D11: 0 | E11: 0 | F11: 0 | G11: 0 | H11: 0 | I11: 0 | J11: 0 | K11: 0 | L11: 0 | M11: 0 | N11: 0 | O11: 0 | P11: =SUM(D11:O11) -> 0 | Q11: ='BOQ Summary'!G14 -> 0
B12: ='BOQ Summary'!B15 -> 006 | C12: ='BOQ Summary'!C15 -> DRAINAGE PLUMBING - SEPTIC, STORMWATER, AG-DRAINAGE | D12: 0 | E12: 0 | F12: 0 | G12: 0 | H12: 0 | I12: 0 | J12: 0 | K12: 0 | L12: 0 | M12: 0 | N12: 0 | O12: 0 | P12: =SUM(D12:O12) -> 0 | Q12: ='BOQ Summary'!G15 -> 0
B13: ='BOQ Summary'!B16 -> 007 | C13: ='BOQ Summary'!C16 -> MEZZANINE & GALLERY / STORAGE FLOOR FRAMING - TIMBER & HARDWARE | D13: 0 | E13: 0 | F13: 0 | G13: 0 | H13: 0 | I13: 0 | J13: 0 | K13: 0 | L13: 0 | M13: 0 | N13: 0 | O13: 0 | P13: =SUM(D13:O13) -> 0 | Q13: ='BOQ Summary'!G16 -> 0
B14: ='BOQ Summary'!B17 -> 008 | C14: ='BOQ Summary'!C17 -> CARPENTRY LABOUR - MEZZANINE FLOOR GRADING & LAYING | D14: 0 | E14: 0 | F14: 0 | G14: 0 | H14: 0 | I14: 0 | J14: 0 | K14: 0 | L14: 0 | M14: 0 | N14: 0 | O14: 0 | P14: =SUM(D14:O14) -> 0 | Q14: ='BOQ Summary'!G17 -> 0
B15: ='BOQ Summary'!B18 -> 009 | C15: ='BOQ Summary'!C18 -> TERMITE TREATMENT - SPRAY, PENETRATION COLLARS, BAIT TRAPS | D15: 0 | E15: 0 | F15: 0 | G15: 0 | H15: 0 | I15: 0 | J15: 0 | K15: 0 | L15: 0 | M15: 0 | N15: 0 | O15: 0 | P15: =SUM(D15:O15) -> 0 | Q15: ='BOQ Summary'!G18 -> 0
B16: ='BOQ Summary'!B19 -> 010 | C16: ='BOQ Summary'!C19 -> GROUND FLOOR & RAISED PLATFORM FRAMING - TIMBER & HARDWARE | D16: 0 | E16: 0 | F16: 0 | G16: 0 | H16: 0 | I16: 0 | J16: 0 | K16: 0 | L16: 0 | M16: 0 | N16: 0 | O16: 0 | P16: =SUM(D16:O16) -> 0 | Q16: ='BOQ Summary'!G19 -> 0
B17: ='BOQ Summary'!B20 -> 011 | C17: ='BOQ Summary'!C20 -> FIRST FLOOR FRAMING - TIMBER & HARDWARE | D17: 0 | E17: 0 | F17: 0 | G17: 0 | H17: 0 | I17: 0 | J17: 0 | K17: 0 | L17: 0 | M17: 0 | N17: 0 | O17: 0 | P17: =SUM(D17:O17) -> 0 | Q17: ='BOQ Summary'!G20 -> 0
B18: ='BOQ Summary'!B21 -> 012 | C18: ='BOQ Summary'!C21 -> FRAMING - TIMBER & HARDWARE (MISC) | D18: 0 | E18: 0 | F18: 0 | G18: 0 | H18: 0 | I18: 0 | J18: 0 | K18: 0 | L18: 0 | M18: 0 | N18: 0 | O18: 0 | P18: =SUM(D18:O18) -> 0 | Q18: ='BOQ Summary'!G21 -> 0
... B50: ='BOQ Summary'!B53 -> 044 | C50: ='BOQ Summary'!C53 -> PROJECT OVERHEAD COSTS | D50: 0 | E50: 0 | F50: 0 | G50: 0 | H50: 0 | I50: 0 | J50: 0 | K50: 0 | L50: 0 | M50: 0 | N50: 0 | O50: 0 | P50: =SUM(D50:O50) -> 0 | Q50: ='BOQ Summary'!G53 -> 0
B51: MONTHLY TOTAL | D51: =SUM(D7:D50) -> 0 | E51: =SUM(E7:E50) -> 0 | F51: =SUM(F7:F50) -> 0 | G51: =SUM(G7:G50) -> 0 | H51: =SUM(H7:H50) -> 0 | I51: =SUM(I7:I50) -> 0 | J51: =SUM(J7:J50) -> 0 | K51: =SUM(K7:K50) -> 0 | ... Q51: =SUM(Q7:Q50) -> 0
B52: CUMULATIVE SPEND | D52: =D51 -> 0 | E52: =D52+E51 -> 0 | F52: =E52+F51 -> 0 | G52: =F52+G51 -> 0 | H52: =G52+H51 -> 0 | I52: =H52+I51 -> 0 | J52: =I52+J51 -> 0 | K52: =J52+K51 -> 0 | L52: =K52+L51 -> 0 | ... O52: =N52+O51 -> 0

Sheet Site Diary
B2: SITE DIARY — DAILY LOG, PERSONNEL & EXPENDITURE
B4: DATE & CONDITIONS | G4: FINANCIALS | J4: LABOUR | L4: SITE ACTIVITIES | O4: OBSERVATIONS & NOTES
B5: Date | C5: Day | D5: Weather | E5: Temp (°C) | F5: Site Supervisor | G5: No. Personnel | H5: Cost Code | I5: Daily Expend. ($) | J5: Total Hours | K5: Trades / Personnel On Site | L5: Works Completed Today | M5: Materials Delivered | N5: Plant & Equipment On Site | O5: Issues / Delays | P5: Visitors On Site | Q5: Health & Safety Observations | R5: Notes / Instructions
C6: =IF(B6="","",TEXT(B6,"DDD")) | I6: 0
C7: =IF(B7="","",TEXT(B7,"DDD")) | I7: 0
C8: =IF(B8="","",TEXT(B8,"DDD")) | I8: 0
C9: =IF(B9="","",TEXT(B9,"DDD")) | I9: 0
C10: =IF(B10="","",TEXT(B10,"DDD")) | I10: 0
C11: =IF(B11="","",TEXT(B11,"DDD")) | I11: 0
C12: =IF(B12="","",TEXT(B12,"DDD")) | I12: 0
C13: =IF(B13="","",TEXT(B13,"DDD")) | I13: 0
C14: =IF(B14="","",TEXT(B14,"DDD")) | I14: 0
C15: =IF(B15="","",TEXT(B15,"DDD")) | I15: 0
C16: =IF(B16="","",TEXT(B16,"DDD")) | I16: 0
C17: =IF(B17="","",TEXT(B17,"DDD")) | I17: 0
... C505: =IF(B505="","",TEXT(B505,"DDD")) | I505: 0
B506: TOTALS | G506: =SUM(G6:G505) -> 0 | I506: =SUM(I6:I505) -> 0 | J506: =SUM(J6:J505) -> 0

Sheet Instructions
B2: MODEL GUIDE — HOW TO USE
B4: COLOUR CODING
B5: Blue text | C5: Input cells — the only cells you should type into.
B6: Black text | C6: Formula cells — auto-calculate. Do not edit.
B7: Green text | C7: Cross-sheet links pulling data from another tab.
B8: Yellow/amber fill (Site Diary col I) | C8: Daily expenditure — financial input that feeds the BOQ Summary.
B10: RAG STATUS
B11: ✔ OK | C11: Forecast Final Cost is at or under the Revised Budget.
B12: ▲ RISK | C12: FFC is 0–10% over Revised Budget. Monitor closely.
B13: ✖ OVER | C13: FFC exceeds Revised Budget by more than 10%. Action required.
B15: SHEET GUIDE & WORKFLOW
B16: Step 1 — BOQ Detail | C16: Enter sub-line items (001.1, 001.2…) with Qty, Unit, Rate. Amounts calculate. These roll up to BOQ Summary original budgets.
B17: Step 2 — BOQ Summary | C17: Review rolled-up budgets. Adjust Builder Margin (D6) and GST rate (E6) if needed. All other columns auto-populate.
B18: Step 3 — PO Register | C18: Enter purchase orders as you engage contractors. PO values feed Committed Cost in BOQ Summary.
B19: Step 4 — Variation Register | C19: Log every variation immediately (even Pending). Only "Approved" status updates the Revised Budget.
B20: Step 5 — Invoice Register | C20: Enter every invoice. "Approved" = certified for payment. "Paid" = payment made. Both count toward Actual CTD.
B21: Step 6 — Progress Claims | C21: Log progress claims per contractor. Link to invoices via Progress Claim No.
B22: Step 7 — Site Diary | C22: Fill in daily — date, weather, personnel, cost code, expenditure, works completed. Column I (Daily Expenditure) is yellow and feeds directly into BOQ Summary Actual Cost to Date. The running totals at the top of the sheet update automatically.
B23: Step 8 — Dashboard | C23: Review weekly. KPI row shows overall project health. RAG column flags cost codes needing attention.
B24: Step 9 — Cash Flow | C24: Rename Month 1–12. Enter forecast spend per CC per month. Compare to Revised Budget (right column).
B26: SITE DIARY — COLUMN GUIDE
B27: Date | C27: Enter the site date. Day of week calculates automatically.
B28: Weather | C28: Fine / Partly Cloudy / Overcast / Raining / Heavy Rain / Windy / Storm
B29: No. Personnel | C29: Total headcount on site that day.
B30: Cost Code | C30: Primary cost code for the day's main works (e.g. "014"). Used to roll up daily expenditure.
B31: Daily Expenditure ($) | C31: Any cost incurred on site that day — materials, labour cash payments, hire items etc. This feeds directly into BOQ Summary Actual CTD for the nominated cost code.
B32: Total Hours | C32: Total labour hours worked across all personnel that day.
B33: Trades / Personnel | C33: List names and trades of everyone on site (e.g. "J. Smith - Carpenter, M. Lee - Electrician").
B34: Works Completed | C34: Detailed description of works completed. Be specific — this is your legal record.
B35: Materials Delivered | C35: Record all material deliveries with supplier, quantity and docket number if possible.
B36: Plant & Equipment | C36: List any hired or owned plant on site (e.g. "Scissor lift — Kennards, 5.8m").
B37: Issues / Delays | C37: Document any delays, defects, disputes, or programme impacts. Critical for variation substantiation.
B38: H&S Observations | C38: Record any safety observations, near misses, incidents, or toolbox talks.
B40: KEY FORMULAS
B41: Revised Budget | C41: Original Budget (from BOQ Detail) + Approved Variations.
B42: Forecast Final Cost | C42: The higher of Committed Cost and Actual CTD — conservative estimate of final cost.
B43: Variance | C43: Revised Budget minus FFC. Positive = under budget. Negative = over budget.
B44: Budget Balance | C44: Revised Budget minus Actual CTD. Remaining unspent budget.
B45: Actual CTD | C45: Sum of Approved + Paid invoices + daily Site Diary expenditure for the cost code.
